Workbook
Name Slicer_Quarter: #N/A

Sheet Raw Data Set
A1: Order_ID | B1: Order_Date | C1: Customer_Name | D1: Region | E1: Product | F1: Category | G1: Quantity | H1: Price | I1: Sales
A2: 1 | B2: 2023-09-02 | C2: Customer_24 | D2: East | E2: Headphones | F2: Electronics | G2: 3 | H2: 10000
A3: 2 | B3: 2023-07-17 | C3: Customer_27 | D3: East | F3: Accessories | G3: 4 | H3: 5000 | I3: 20000
A4: 3 | B4: 2023-12-21 | C4: Customer_31 | D4: East | F4: Accessories | G4: 3 | H4: 1000 | I4: 3000
A5: 4 | B5: 2023-11-23 | C5: Customer_32 | D5: south | E5: Headphones | G5: 3
A6: 5 | B6: 2023-08-16 | C6: Customer_12 | E6: laptop | F6: Electronics | G6: 2
A7: 6 | B7: 2023-03-08 | C7: Customer_29 | D7: south | E7: Phone | F7: Electronics | H7: 30000
A8: 7 | C8: Customer_12 | D8: South | E8: laptop | H8: 10000
A9: 8 | B9: 2023-05-08 | C9: Customer_33 | D9: West | E9: Laptop | F9: Accessories | H9: 10000
A10: 9 | B10: 2023-09-01 | C10: Customer_7 | H10: 5000
A11: 10 | B11: 2023-04-11 | C11: Customer_35 | D11: East | E11: Monitor | F11: Accessories | G11: 5
A12: 11 | C12: Customer_13 | D12: south | E12: laptop | F12: Electronics | G12: 4 | H12: 1000 | I12: 4000
A13: 12 | B13: 2023-03-23 | C13: Customer_50 | D13: East | E13: Tablet | F13: Electronics | H13: 1000
A14: 13 | C14: Customer_8 | D14: West | E14: Phone | G14: 3 | H14: 30000 | I14: 90000
A15: 14 | B15: 2023-08-25 | D15: North | E15: Monitor | F15: Accessories | G15: 5
A16: 15 | B16: 2023-04-30 | C16: Customer_2 | D16: East | E16: laptop | F16: Accessories | G16: 5 | H16: 20000 | I16: 100000
A17: 16 | C17: Customer_2 | D17: North | E17: laptop | F17: Electronics | G17: 2
A18: 18 | B18: 2023-04-05 | C18: Customer_33 | E18: Monitor | G18: 3 | H18: 1000 | I18: 3000
A19: 19 | B19: 2023-05-20 | D19: south | E19: Laptop | F19: Electronics | G19: 1 | H19: 10000
A20: 20 | C20: Customer_35 | D20: south | E20: Headphones | G20: 1 | H20: 5000 | I20: 5000
A21: 21 | C21: Customer_44 | E21: Laptop | F21: Electronics | H21: 1000
A22: 22 | B22: 2023-08-11 | C22: Customer_1 | G22: 2 | H22: 20000 | I22: 40000
A23: 23 | B23: 2023-05-16 | D23: south | E23: Monitor | F23: Electronics | G23: 1
A24: 24 | B24: 2023-01-11 | C24: Customer_41 | D24: East | H24: 10000
A25: 25 | B25: 2023-07-18 | C25: Customer_38 | D25: south | E25: Tablet | F25: Accessories | G25: 2 | H25: 1000 | I25: 2000
A26: 26 | B26: 2023-09-05 | C26: Customer_44 | D26: East | E26: Tablet | F26: Accessories | H26: 20000
A27: 27 | B27: 2023-11-21 | C27: Customer_46 | D27: South | E27: Phone | F27: Electronics | G27: 2
A28: 28 | B28: 2023-08-03 | C28: Customer_24 | D28: West | E28: Phone | F28: Accessories | G28: 2
A29: 29 | B29: 2023-02-10 | C29: Customer_46 | D29: South | E29: Headphones | F29: Electronics | H29: 5000
A30: 30 | B30: 2023-03-16 | C30: Customer_36 | D30: South | E30: laptop | F30: Electronics | G30: 2
A31: 31 | B31: 2023-03-30 | D31: North | F31: Electronics | H31: 30000
A32: 32 | B32: 2023-12-16 | C32: Customer_19 | D32: south | E32: Monitor | F32: Electronics | G32: 4
A33: 33 | B33: 2023-10-20 | C33: Customer_38 | D33: South | E33: Tablet | F33: Electronics
A34: 34 | B34: 2023-12-06 | C34: Customer_27 | E34: Laptop
A35: 35 | B35: 2023-10-26 | C35: Customer_20 | D35: East | E35: Laptop | F35: Electronics | G35: 1 | H35: 1000 | I35: 1000
A36: 36 | B36: 2023-02-18 | E36: Headphones | F36: Accessories | G36: 3 | H36: 1000 | I36: 3000
A37: 37 | B37: 2023-08-29 | C37: Customer_4 | D37: South | E37: Headphones | G37: 4 | H37: 10000
A38: 38 | B38: 2023-08-05 | C38: Customer_41 | D38: North | E38: Monitor | F38: Electronics | G38: 2
A39: 39 | B39: 2023-04-17 | C39: Customer_12 | D39: North | F39: Electronics | H39: 30000
A40: 40 | B40: 2023-01-22 | C40: Customer_4 | D40: East | E40: Phone | F40: Electronics
...

Sheet Notes
A1: Sales Dataset — Data Cleaning & Analysis
A2: Prepared with Excel formulas
A4: WHAT WAS DONE
A5: 1. Removed duplicates: checked for exact duplicate rows (none found) and duplicate Order_IDs (none found).
A6: 2. Standardized text fields: trimmed whitespace and fixed inconsistent capitalization in Region, Product,using TRIM and PROPER
A7: and Category (e.g. "south " / "South" -> "South", "laptop" / "Laptop" -> "Laptop").
A8: 3. Handled missing values:
A9: -Missing region detucted comparing with Customer_Name and Order_Date and category detucted using python by getting the mode
A10: - Product / Customer_Name -> labeled "Unknown" / "Unknown Customer".
A11: - Missing Quantity / Price -> filled with the median value for that Product (a standard, defensible
A12: imputation method), then Sales was recalculated as Quantity x Price for every row.
A13: - Missing Order_Date ->imputed using median of date from the existing data
... A29: - To look up an order, go to the 'look up' sheet and type an Order_ID into the yellow cell (B4).

Sheet Retail sales Data
A1: Order_ID | B1: Order_Date | C1: Customer_Name | D1: Region | E1: Product | F1: Category | G1: Quantity | H1: Price | I1: Sales | J1: Year | K1: Month | L1: Quarter | M1: Data_Quality_Flag | N1: Quantity_Flag | O1: Price_Flag
A2: 1 | B2: 45171 | C2: Customer_24 | D2: East | E2: Headphones | F2: Electronics | G2: 3 | H2: 10000 | I2: =G2*H2 -> 30000 | J2: =IF(B2="","Unknown",YEAR(B2)) -> 2023 | K2: =IF(B2="","Unknown",TEXT(B2,"mmmm")) -> September | L2: =IF(B2="","Unknown","Q"&ROUNDUP(MONTH(B2)/3,0)) -> Q3 | M2: Original | N2: Original | O2: Original
A3: 2 | B3: 45124 | C3: Customer_27 | D3: East | E3: Unknown Product | F3: Accessories | G3: 4 | H3: 5000 | I3: =G3*H3 -> 20000 | J3: =IF(B3="","Unknown",YEAR(B3)) -> 2023 | K3: =IF(B3="","Unknown",TEXT(B3,"mmmm")) -> July | L3: =IF(B3="","Unknown","Q"&ROUNDUP(MONTH(B3)/3,0)) -> Q3 | M3: Product unknown | N3: Original | O3: Original
A4: 3 | B4: 45281 | C4: Customer_31 | D4: East | E4: Unknown Product | F4: Accessories | G4: 3 | H4: 1000 | I4: =G4*H4 -> 3000 | J4: =IF(B4="","Unknown",YEAR(B4)) -> 2023 | K4: =IF(B4="","Unknown",TEXT(B4,"mmmm")) -> December | L4: =IF(B4="","Unknown","Q"&ROUNDUP(MONTH(B4)/3,0)) -> Q4 | M4: Product unknown | N4: Original | O4: Original
A5: 4 | B5: 45253 | C5: Customer_32 | D5: South | E5: Headphones | F5: Accessories | G5: 3 | H5: 10000 | I5: =G5*H5 -> 30000 | J5: =IF(B5="","Unknown",YEAR(B5)) -> 2023 | K5: =IF(B5="","Unknown",TEXT(B5,"mmmm")) -> November | L5: =IF(B5="","Unknown","Q"&ROUNDUP(MONTH(B5)/3,0)) -> Q4 | M5: Imputed Category | N5: Original | O5: Imputed (Median)
A6: 5 | B6: 45154 | C6: Customer_12 | D6: South | E6: Laptop | F6: Electronics | G6: 2 | H6: 10000 | I6: =G6*H6 -> 20000 | J6: =IF(B6="","Unknown",YEAR(B6)) -> 2023 | K6: =IF(B6="","Unknown",TEXT(B6,"mmmm")) -> August | L6: =IF(B6="","Unknown","Q"&ROUNDUP(MONTH(B6)/3,0)) -> Q3 | M6: Original | N6: Original | O6: Imputed (Median)
A7: 6 | B7: 44993 | C7: Customer_29 | D7: South | E7: Phone | F7: Electronics | G7: 3 | H7: 30000 | I7: =G7*H7 -> 90000 | J7: =IF(B7="","Unknown",YEAR(B7)) -> 2023 | K7: =IF(B7="","Unknown",TEXT(B7,"mmmm")) -> March | L7: =IF(B7="","Unknown","Q"&ROUNDUP(MONTH(B7)/3,0)) -> Q1 | M7: Original | N7: Imputed (Median) | O7: Original
A8: 7 | B8: 45096 | C8: Customer_12 | D8: South | E8: Laptop | F8: Electronics | G8: 3 | H8: 10000 | I8: =G8*H8 -> 30000 | J8: =IF(B8="","Unknown",YEAR(B8)) -> 2023 | K8: =IF(B8="","Unknown",TEXT(B8,"mmmm")) -> June | L8: =IF(B8="","Unknown","Q"&ROUNDUP(MONTH(B8)/3,0)) -> Q2 | M8: Date imputed (median); Category Imputed | N8: Imputed (Median) | O8: Original
A9: 8 | B9: 45054 | C9: Customer_33 | D9: West | E9: Laptop | F9: Accessories | G9: 3 | H9: 10000 | I9: =G9*H9 -> 30000 | J9: =IF(B9="","Unknown",YEAR(B9)) -> 2023 | K9: =IF(B9="","Unknown",TEXT(B9,"mmmm")) -> May | L9: =IF(B9="","Unknown","Q"&ROUNDUP(MONTH(B9)/3,0)) -> Q2 | M9: Original | N9: Imputed (Median) | O9: Original
A10: 9 | B10: 45170 | C10: Customer_7 | D10: West | E10: Unknown Product | F10: Unknown Category | G10: 3 | H10: 5000 | I10: =G10*H10 -> 15000 | J10: =IF(B10="","Unknown",YEAR(B10)) -> 2023 | K10: =IF(B10="","Unknown",TEXT(B10,"mmmm")) -> September | L10: =IF(B10="","Unknown","Q"&ROUNDUP(MONTH(B10)/3,0)) -> Q3 | M10: Product unknown; Category unknown | N10: Imputed (Median) | O10: Original
A11: 10 | B11: 45027 | C11: Customer_35 | D11: East | E11: Monitor | F11: Accessories | G11: 5 | H11: 10000 | I11: =G11*H11 -> 50000 | J11: =IF(B11="","Unknown",YEAR(B11)) -> 2023 | K11: =IF(B11="","Unknown",TEXT(B11,"mmmm")) -> April | L11: =IF(B11="","Unknown","Q"&ROUNDUP(MONTH(B11)/3,0)) -> Q2 | M11: Original | N11: Original | O11: Imputed (Median)
A12: 11 | B12: 45096 | C12: Customer_13 | D12: South | E12: Laptop | F12: Electronics | G12: 4 | H12: 1000 | I12: =G12*H12 -> 4000 | J12: =IF(B12="","Unknown",YEAR(B12)) -> 2023 | K12: =IF(B12="","Unknown",TEXT(B12,"mmmm")) -> June | L12: =IF(B12="","Unknown","Q"&ROUNDUP(MONTH(B12)/3,0)) -> Q2 | M12: Date imputed (median) | N12: Original | O12: Original
A13: 12 | B13: 45008 | C13: Customer_50 | D13: East | E13: Tablet | F13: Electronics | G13: 3 | H13: 1000 | I13: =G13*H13 -> 3000 | J13: =IF(B13="","Unknown",YEAR(B13)) -> 2023 | K13: =IF(B13="","Unknown",TEXT(B13,"mmmm")) -> March | L13: =IF(B13="","Unknown","Q"&ROUNDUP(MONTH(B13)/3,0)) -> Q1 | M13: Original | N13: Imputed (Median) | O13: Original
... A78: 78 | B78: 45262 | C78: Customer_43 | D78: East | E78: Headphones | F78: Electronics | G78: 2 | H78: 10000 | I78: =G78*H78 -> 20000 | J78: =IF(B78="","Unknown",YEAR(B78)) -> 2023 | K78: =IF(B78="","Unknown",TEXT(B78,"mmmm")) -> December | L78: =IF(B78="","Unknown","Q"&ROUNDUP(MONTH(B78)/3,0)) -> Q4 | M78: Original | N78: Original | O78: Original
A79: 79 | B79: 45231 | C79: Customer_5 | D79: North | E79: Monitor | F79: Electronics | G79: 3 | H79: 5000 | I79: =G79*H79 -> 15000 | J79: =IF(B79="","Unknown",YEAR(B79)) -> 2023 | K79: =IF(B79="","Unknown",TEXT(B79,"mmmm")) -> November | L79: =IF(B79="","Unknown","Q"&ROUNDUP(MONTH(B79)/3,0)) -> Q4 | M79: Imputed Category | N79: Imputed (Median) | O79: Original | Q79: =MEDIAN(H11:H247) -> 10000
A80: 80 | B80: 45270 | C80: Customer_44 | D80: North | E80: Laptop | F80: Electronics | G80: 3 | H80: 10000 | I80: =G80*H80 -> 30000 | J80: =IF(B80="","Unknown",YEAR(B80)) -> 2023 | K80: =IF(B80="","Unknown",TEXT(B80,"mmmm")) -> December | L80: =IF(B80="","Unknown","Q"&ROUNDUP(MONTH(B80)/3,0)) -> Q4 | M80: Original | N80: Imputed (Median) | O80: Original
A81: 81 | B81: 44979 | C81: Customer_23 | D81: East | E81: Unknown Product | F81: Unknown Category | G81: 5 | H81: 10000 | I81: =G81*H81 -> 50000 | J81: =IF(B81="","Unknown",YEAR(B81)) -> 2023 | K81: =IF(B81="","Unknown",TEXT(B81,"mmmm")) -> February | L81: =IF(B81="","Unknown","Q"&ROUNDUP(MONTH(B81)/3,0)) -> Q1 | M81: Product unknown; Category unknown | N81: Original | O81: Original
A82: 82 | B82: 44936 | C82: Customer_33 | D82: West | E82: Phone | F82: Electronics | G82: 2 | H82: 5000 | I82: =G82*H82 -> 10000 | J82: =IF(B82="","Unknown",YEAR(B82)) -> 2023 | K82: =IF(B82="","Unknown",TEXT(B82,"mmmm")) -> January | L82: =IF(B82="","Unknown","Q"&ROUNDUP(MONTH(B82)/3,0)) -> Q1 | M82: Original | N82: Original | O82: Original
A83: 83 | B83: 45007 | C83: Customer_22 | D83: East | E83: Monitor | F83: Electronics | G83: 3 | H83: 10000 | I83: =G83*H83 -> 30000 | J83: =IF(B83="","Unknown",YEAR(B83)) -> 2023 | K83: =IF(B83="","Unknown",TEXT(B83,"mmmm")) -> March | L83: =IF(B83="","Unknown","Q"&ROUNDUP(MONTH(B83)/3,0)) -> Q1 | M83: Original | N83: Imputed (Median) | O83: Imputed (Median)
A84: 84 | B84: 45109 | C84: Unknown Customer | D84: East | E84: Unknown Product | F84: Accessories | G84: 2 | H84: 10000 | I84: =G84*H84 -> 20000 | J84: =IF(B84="","Unknown",YEAR(B84)) -> 2023 | K84: =IF(B84="","Unknown",TEXT(B84,"mmmm")) -> July | L84: =IF(B84="","Unknown","Q"&ROUNDUP(MONTH(B84)/3,0)) -> Q3 | M84: Product unknown | N84: Original | O84: Imputed (Median)
A85: 85 | B85: 45122 | C85: Customer_12 | D85: South | E85: Tablet | F85: Accessories | G85: 3 | H85: 30000 | I85: =G85*H85 -> 90000 | J85: =IF(B85="","Unknown",YEAR(B85)) -> 2023 | K85: =IF(B85="","Unknown",TEXT(B85,"mmmm")) -> July | L85: =IF(B85="","Unknown","Q"&ROUNDUP(MONTH(B85)/3,0)) -> Q3 | M85: Original | N85: Imputed (Median) | O85: Original
A86: 86 | B86: 45135 | C86: Customer_8 | D86: South | E86: Headphones | F86: Electronics | G86: 3 | H86: 1000 | I86: =G86*H86 -> 3000 | J86: =IF(B86="","Unknown",YEAR(B86)) -> 2023 | K86: =IF(B86="","Unknown",TEXT(B86,"mmmm")) -> July | L86: =IF(B86="","Unknown","Q"&ROUNDUP(MONTH(B86)/3,0)) -> Q3 | M86: Original | N86: Imputed (Median) | O86: Original
A87: 87 | B87: 45096 | C87: Customer_6 | D87: West | E87: Tablet | F87: Accessories | G87: 5 | H87: 10000 | I87: =G87*H87 -> 50000 | J87: =IF(B87="","Unknown",YEAR(B87)) -> 2023 | K87: =IF(B87="","Unknown",TEXT(B87,"mmmm")) -> June | L87: =IF(B87="","Unknown","Q"&ROUNDUP(MONTH(B87)/3,0)) -> Q2 | M87: Original | N87: Original | O87: Original
A88: 88 | B88: 45228 | C88: Unknown Customer | D88: East | E88: Laptop | F88: Electronics | G88: 3 | H88: 5000 | I88: =G88*H88 -> 15000 | J88: =IF(B88="","Unknown",YEAR(B88)) -> 2023 | K88: =IF(B88="","Unknown",TEXT(B88,"mmmm")) -> October | L88: =IF(B88="","Unknown","Q"&ROUNDUP(MONTH(B88)/3,0)) -> Q4 | M88: Imputed Category | N88: Original | O88: Original
A89: 89 | B89: 45165 | C89: Customer_32 | D89: East | E89: Monitor | F89: Electronics | G89: 5 | H89: 10000 | I89: =G89*H89 -> 50000 | J89: =IF(B89="","Unknown",YEAR(B89)) -> 2023 | K89: =IF(B89="","Unknown",TEXT(B89,"mmmm")) -> August | L89: =IF(B89="","Unknown","Q"&ROUNDUP(MONTH(B89)/3,0)) -> Q3 | M89: Imputed Category | N89: Original | O89: Imputed (Median)
A90: 90 | B90: 45151 | C90: Customer_21 | D90: East | E90: Laptop | F90: Electronics | G90: 3 | H90: 10000 | I90: =G90*H90 -> 30000 | J90: =IF(B90="","Unknown",YEAR(B90)) -> 2023 | K90: =IF(B90="","Unknown",TEXT(B90,"mmmm")) -> August | L90: =IF(B90="","Unknown","Q"&ROUNDUP(MONTH(B90)/3,0)) -> Q3 | M90: Imputed Category | N90: Original | O90: Original
A91: 91 | B91: 45243 | C91: Customer_6 | D91: North | E91: Headphones | F91: Electronics | G91: 1 | H91: 10000 | I91: =G91*H91 -> 10000 | J91: =IF(B91="","Unknown",YEAR(B91)) -> 2023 | K91: =IF(B91="","Unknown",TEXT(B91,"mmmm")) -> November | L91: =IF(B91="","Unknown","Q"&ROUNDUP(MONTH(B91)/3,0)) -> Q4 | M91: Original | N91: Original | O91: Original
... A250: 250 | B250: 45088 | C250: Customer_50 | D250: East | E250: Unknown Product | F250: Electronics | G250: 2 | H250: 1000 | I250: =G250*H250 -> 2000 | J250: =IF(B250="","Unknown",YEAR(B250)) -> 2023 | K250: =IF(B250="","Unknown",TEXT(B250,"mmmm")) -> June | L250: =IF(B250="","Unknown","Q"&ROUNDUP(MONTH(B250)/3,0)) -> Q2 | M250: Product unknown | N250: Original | O250: Original

Sheet Top 5 Ranking
A1: Top 5 Products by Total Sales
A4: All Products (helper table) | E4: Top 5 Ranking (formula-driven)
A5: Row Labels | B5: Revenue | E5: Rank | F5: Product | G5: Total Sales
A6: Headphones | B6: 1010000 | E6: 1 | F6: =INDEX($A$6:$A$11,MATCH(G6,$B$6:$B$11,0)) -> Laptop | G6: =LARGE($B$6:$B$11,E6) -> 2140000
A7: Laptop | B7: 2140000 | E7: 2 | F7: =INDEX($A$6:$A$11,MATCH(G7,$B$6:$B$11,0)) -> Monitor | G7: =LARGE($B$6:$B$11,E7) -> 1960000
A8: Monitor | B8: 1960000 | E8: 3 | F8: =INDEX($A$6:$A$11,MATCH(G8,$B$6:$B$11,0)) -> Tablet | G8: =LARGE($B$6:$B$11,E8) -> 1297000
A9: Phone | B9: 1195000 | E9: 4 | F9: =INDEX($A$6:$A$11,MATCH(G9,$B$6:$B$11,0)) -> Phone | G9: =LARGE($B$6:$B$11,E9) -> 1195000
A10: Tablet | B10: 1297000 | E10: 5 | F10: =INDEX($A$6:$A$11,MATCH(G10,$B$6:$B$11,0)) -> Unknown Product | G10: =LARGE($B$6:$B$11,E10) -> 1177000
A11: Unknown Product | B11: 1177000
A12: Grand Total | B12: 8779000

Sheet Region wise Sales
A1: Total Sales by Region
A4: Region | B4: Revenue | C4: No of orders | D4: Average Sale | E4: % of Total Revenue
A5: East | B5: 399000 | C5: 13 | D5: =IFERROR(B5/C5,0) -> 30692.308 | E5: =IFERROR(B5/SUM($B$5:$B$9),0) -> 0.11478711
A6: North | B6: 265000 | C6: 9 | D6: =IFERROR(B6/C6,0) -> 29444.444 | E6: =IFERROR(B6/SUM($B$5:$B$9),0) -> 0.076237054
A7: South | B7: 987000 | C7: 22 | D7: =IFERROR(B7/C7,0) -> 44863.636 | E7: =IFERROR(B7/SUM($B$5:$B$9),0) -> 0.28394707
A8: West | B8: 87000 | C8: 5 | D8: =IFERROR(B8/C8,0) -> 17400 | E8: =IFERROR(B8/SUM($B$5:$B$9),0) -> 0.025028769
A9: Grand Total | B9: 1738000 | C9: 49

Sheet Monthly Sales
A1: Monthly Sales Summary (2023)
A3: Row Labels | B3: Sum of Sales | C3: Count of Order_ID | D3: Count of Order_ID
A4: January | B4: 695000 | C4: 18 | D4: =IFERROR(B4/C4,0) -> 38611.111
A5: February | B5: 903000 | C5: 21 | D5: =IFERROR(B5/C5,0) -> 43000
A6: March | B6: 696000 | C6: 20 | D6: =IFERROR(B6/C6,0) -> 34800
A7: April | B7: 788000 | C7: 16 | D7: =IFERROR(B7/C7,0) -> 49250
A8: May | B8: 485000 | C8: 21 | D8: =IFERROR(B8/C8,0) -> 23095.238
A9: June | B9: 1720000 | C9: 49 | D9: =IFERROR(B9/C9,0) -> 35102.041
A10: July | B10: 496000 | C10: 18 | D10: =IFERROR(B10/C10,0) -> 27555.556
A11: August | B11: 648000 | C11: 21 | D11: =IFERROR(B11/C11,0) -> 30857.143
A12: September | B12: 610000 | C12: 16 | D12: =IFERROR(B12/C12,0) -> 38125
A13: October | B13: 408000 | C13: 14 | D13: =IFERROR(B13/C13,0) -> 29142.857
A14: November | B14: 565000 | C14: 10 | D14: =IFERROR(B14/C14,0) -> 56500
A15: December | B15: 765000 | C15: 25 | D15: =IFERROR(B15/C15,0) -> 30600
A16: Grand Total | B16: 8779000 | C16: 249 | D16: =IFERROR(B16/C16,0) -> 35257.028

Sheet look up
A1: Order Lookup Tool
A4: Enter Order_ID: | B4: 141
A6: VLOOKUP Results
A7: Order_Date | B7: =VLOOKUP($B$4,'Retail sales Data'!$A$2:$L$250,2,FALSE()) -> 44927
A8: Customer_Name | B8: =VLOOKUP($B$4,'Retail sales Data'!$A$2:$L$250,3,FALSE()) -> Customer_17
A9: Region | B9: =VLOOKUP($B$4,'Retail sales Data'!$A$2:$L$250,4,FALSE()) -> South
A10: Product | B10: =VLOOKUP($B$4,'Retail sales Data'!$A$2:$L$250,5,FALSE()) -> Tablet
A11: Category | B11: =VLOOKUP($B$4,'Retail sales Data'!$A$2:$L$250,6,FALSE()) -> Electronics
A12: Quantity | B12: =VLOOKUP($B$4,'Retail sales Data'!$A$2:$L$250,7,FALSE()) -> 2
A13: Price | B13: =VLOOKUP($B$4,'Retail sales Data'!$A$2:$L$250,8,FALSE()) -> 10000
A14: Sales | B14: =VLOOKUP($B$4,'Retail sales Data'!$A$2:$L$250,9,FALSE()) -> 20000
